Workbook

Sheet Calculator
B1: Cost reverse calculator: price per km + margin -> cost -> line items
B2: Margin is on PRICE (price = cost / (1 - margin)), same as the Summary sheet. Yellow cells are inputs.
B3: 1. Inputs
B4: Vehicle class | C4: 4W - Dry | D4: pick from list
B5: One-way distance (km) | C5: 120
B6: Legs billed (2 = round trip) | C6: 2 | D6: Billable km = one-way x legs
B7: Billable km | C7: =C5*C6
B8: Quoted price per billable km (THB/km) | C8: 20.29 | D8: the number you want to reverse-engineer
B9: Margin on price | C9: 0.3 | D9: Summary sheet uses 30%, Assumption row 49 says 25%
B10: Trips per vehicle per month | C10: 25 | D10: utilisation: spreads fixed cost
B11: Diesel price (THB/L) | C11: 48
B12: (class index) | C12: =MATCH(C4,Inputs!$C$3:$L$3,0) | D12: helper
B14: 2. Price -> implied cost (exact)
B15: Price per trip | C15: =C8*C7 | D15: price/km x billable km
B16: Margin in THB | C16: =C15*C9
B17: Implied cost per trip | C17: =C15-C16 | D17: price x (1 - margin)
B18: Implied cost per km | C18: =C17/C7
B20: 3. V: variable cost, THB per km (scales with distance)
B21: Fuel | C21: =C11/INDEX(Inputs!$C$4:$L$4,$C$12) | D21: diesel price / km per litre
B22: Oil + filter | C22: =INDEX(Inputs!$C$5:$L$5,$C$12)/INDEX(Inputs!$C$6:$L$6,$C$12) | D22: cost per change / change interval
B23: Tyres | C23: =INDEX(Inputs!$C$7:$L$7,$C$12)*INDEX(Inputs!$C$8:$L$8,$C$12)/INDEX(Inputs!$C$9:$L$9,$C$12) | D23: tyres x price / tyre life
B24: Maintenance | C24: =INDEX(Inputs!$C$10:$L$10,$C$12) | D24: assumption from workbook
B25: V (total variable, THB/km) | C25: =SUM(C21:C24) | D25: the slope
B27: 4. F: fixed cost per trip, THB (does not scale with km)
B28: Driver allowance | C28: =INDEX(Inputs!$C$14:$L$14,$C$12)*IF(C7>INDEX(Inputs!$C$22:$L$22,$C$12),2,1) | D28: base rate, doubled if billable km > threshold
B29: Non-receipt expenses (tolls etc.) | C29: =INDEX(Inputs!$C$17:$L$17,$C$12)*IF(C7>INDEX(Inputs!$C$22:$L$22,$C$12),2,1) | D29: base rate, doubled if billable km > threshold
B30: Driver salary | C30: =INDEX(Inputs!$C$13:$L$13,$C$12)/C10 | D30: per month / trips per month
B31: Office overhead | C31: =INDEX(Inputs!$C$18:$L$18,$C$12)/C10 | D31: per month / trips per month
B32: Insurance | C32: =INDEX(Inputs!$C$15:$L$15,$C$12)/(C10*12) | D32: per year / trips per year
B33: Annual tax + GPS | C33: =INDEX(Inputs!$C$16:$L$16,$C$12)/(C10*12) | D33: per year / trips per year
B34: Depreciation | C34: =INDEX(Inputs!$C$19:$L$19,$C$12)*(1-INDEX(Inputs!$C$20:$L$20,$C$12))/INDEX(Inputs!$C$21:$L$21,$C$12)/(C10*12) | D34: (price - salvage) / life / trips per year
B35: Reefer genset fuel | C35: =IF(INDEX(Inputs!$C$11:$L$11,$C$12)>0,INDEX(Inputs!$C$11:$L$11,$C$12)*(C5/INDEX(Inputs!$C$12:$L$12,$C$12))*C11,0) | D35: L/hr x hours (one-way km / speed) x diesel price
B36: F (total fixed, THB/trip) | C36: =SUM(C28:C35) | D36: the intercept
B38: 5. Model cost vs implied cost: cost = V x km + F
B39: Model cost per trip | C39: =C25*C7+C36 | D39: V x km + F
B40: Model cost per km | C40: =C39/C7
B41: Gap: implied cost - model cost (THB/trip) | C41: =C17-C39 | D41: > 0: price implies MORE cost than the model explains
B42: Margin actually earned if model cost is true | C42: =1-C39/C15 | D42: 1 - model cost / price
B43: Price/km needed for the target margin | C43: =C39/(1-C9)/C7 | D43: model cost / (1 - margin) / km
B45: 6. What would have to be true to close the gap (one lever at a time)
...

Sheet Inputs
A1: Per-class assumptions (values copied from PLP Cost Structure.xlsx > Assumption). Edit blue cells.
A3: Item | B3: Unit | C3: 4W - Dry | D3: 4W - Reefer | E3: 6W - Dry | F3: 6W - Reefer | G3: 10W - Dry | H3: 10W - Reefer | I3: Container - Dry | J3: Container - Reefer | K3: Drayage - Dry | L3: Drayage - Reefer
A4: Fuel economy (src row 15) | B4: km/L | C4: 9.6 | D4: 9.6 | E4: 3.8 | F4: 3.8 | G4: 3.4 | H4: 3.4 | I4: 2.5 | J4: 2.5 | K4: 2.5 | L4: 2.5
A5: Oil + filter cost per change (src row 17) | B5: THB | C5: 1500 | D5: 1500 | E5: 3000 | F5: 3000 | G5: 6000 | H5: 6000 | I5: 10000 | J5: 10000 | K5: 10000 | L5: 10000
A6: Oil change interval (src row 18) | B6: km | C6: 10000 | D6: 10000 | E6: 10000 | F6: 10000 | G6: 10000 | H6: 10000 | I6: 10000 | J6: 10000 | K6: 10000 | L6: 10000
A7: Tyres per vehicle (src row 20) | B7: count | C7: 4 | D7: 4 | E7: 6 | F7: 6 | G7: 10 | H7: 10 | I7: 22 | J7: 22 | K7: 22 | L7: 22
A8: Price per tyre (src row 21) | B8: THB | C8: 3500 | D8: 3500 | E8: 5000 | F8: 5000 | G8: 6000 | H8: 6000 | I8: 10000 | J8: 10000 | K8: 10000 | L8: 10000
A9: Tyre life (src row 23) | B9: km | C9: 50000 | D9: 50000 | E9: 80000 | F9: 80000 | G9: 100000 | H9: 100000 | I9: 100000 | J9: 100000 | K9: 100000 | L9: 100000
A10: Maintenance (src row 25) | B10: THB/km | C10: 0.4 | D10: 0.4 | E10: 1.1 | F10: 1.1 | G10: 1.5 | H10: 1.5 | I10: 1.5 | J10: 1.5 | K10: 1.5 | L10: 1.5
A11: Reefer genset consumption (src row 28) | B11: L/hr | C11: 0 | D11: 3.75 | E11: 0 | F11: 3.75 | G11: 0 | H11: 3.75 | I11: 0 | J11: 4 | K11: 0 | L11: 4
A12: Average speed (src row 29) | B12: km/hr | C12: 90 | D12: 90 | E12: 90 | F12: 90 | G12: 90 | H12: 90 | I12: 65 | J12: 65 | K12: 65 | L12: 65
A13: Driver salary (src row 35) | B13: THB/month | C13: 12000 | D13: 12000 | E13: 12000 | F13: 12000 | G13: 12000 | H13: 12000 | I13: 12000 | J13: 12000 | K13: =30*400 | L13: 12000
A14: Driver allowance (base rate) (src row 45) | B14: THB/trip | C14: 300 | D14: 300 | E14: 400 | F14: 400 | G14: 500 | H14: 500 | I14: 500 | J14: 500 | K14: 500 | L14: 500
A15: Insurance (cargo + vehicle) (src row 37) | B15: THB/year | C15: 25000 | D15: 25000 | E15: 40000 | F15: 40000 | G15: 60000 | H15: 60000 | I15: 110000 | J15: 120000 | K15: 110000 | L15: 120000
A16: Annual tax + GPS (src row 38) | B16: THB/year | C16: 5000 | D16: 5000 | E16: 6500 | F16: 6500 | G16: 8000 | H16: 8000 | I16: 10000 | J16: 10000 | K16: 10000 | L16: 10000
A17: Non-receipt expenses (base rate) (src row 46) | B17: THB/trip | C17: 200 | D17: 200 | E17: 250 | F17: 250 | G17: 300 | H17: 300 | I17: 300 | J17: 300 | K17: 300 | L17: 300
A18: Office overhead (src row 40) | B18: THB/vehicle/month | C18: 6000 | D18: 6000 | E18: 7000 | F18: 7000 | G18: 8000 | H18: 8000 | I18: 10000 | J18: 10000 | K18: 10000 | L18: 10000
A19: Vehicle price (src row 41) | B19: THB | C19: 900000 | D19: 1300000 | E19: 1900000 | F19: 2600000 | G19: 2900000 | H19: 3700000 | I19: 4100000 | J19: 4600000 | K19: 4100000 | L19: 4600000
A20: Salvage value (src row 42) | B20: % of price | C20: 0.05 | D20: 0.05 | E20: 0.05 | F20: 0.05 | G20: 0.05 | H20: 0.05 | I20: 0.05 | J20: 0.05 | K20: 0.05 | L20: 0.05
A21: Depreciation life (src row 43) | B21: years | C21: 15 | D21: 15 | E21: 15 | F21: 15 | G21: 15 | H21: 15 | I21: 15 | J21: 15 | K21: 15 | L21: 15
A22: Allowance threshold (billable km) (src row 11) | B22: km | C22: 200 | D22: 200 | E22: 200 | F22: 200 | G22: 200 | H22: 200 | I22: 200 | J22: 200 | K22: 200 | L22: 200
