Workbook

Sheet PP_CleanTopic
A1: Category | B1: Cost Item | C1: Department | D1: Treatment per Trip | E1: Note
A2: 1. Vehicle Operating Cost | B2: ค่าน้ำมันเชื้อเพลิง | C2: Estimation | D2: {Distance} × fuel consumption × {fuel price}
B3: ค่าน้ำมันหล่อลื่นและไส้กรอง | C3: ฝ่ายซ่อมบำรุง | D3: Allocate by km
B4: ค่ายางรถ | C4: ฝ่ายซ่อมบำรุง | D4: Allocate by km
B5: ค่าซ่อมแซมและบำรุงรักษา | C5: ฝ่ายซ่อมบำรุง | D5: Allocate by km | E5: Can be disaggregated into: Preventive Maintenance + Periodic Maintenance + Failure Maintenance
A6: 2. Vehicle Ownership / Fixed Cost | B6: ค่าเสื่อมราคารถ | C6: ฝ่ายซ่อมบำรุง / ฝ่ายบัญชี | D6: Allocate by km / trip / operating day
B7: ค่าเบี้ยประกันภัยรถ | C7: ฝ่ายซ่อมบำรุง / ฝ่ายบัญชี | D7: Allocate by trip / operating day
B8: ค่าเบี้ยประกันสินค้า | C8: ฝ่ายซ่อมบำรุง / ฝ่ายบัญชี | D8: Per trip or allocated based on shipment
B9: ภาษีรถประจำปี | C9: ฝ่ายซ่อมบำรุง / ฝ่ายบัญชี | D9: Allocate by operating days/trips
B10: ค่าระบบ GPS | C10: ฝ่ายซ่อมบำรุง / ฝ่ายบัญชี | D10: Allocate by month → trip
A11: 3. Human Cost | B11: เงินเดือนพนักงานขับรถ | C11: ฝ่ายบัญชี / ฝ่ายบุคคล | D11: Allocate by working hours/days/trip
B12: ค่าเบี้ยเลี้ยงพนักงานขับรถ | C12: ฝ่ายบัญชี / ฝ่ายบุคคล | D12: Actual per trip
B13: ค่าเบี้ยเลี้ยงอัตราฐาน | C13: ฝ่ายบัญชี / ฝ่ายบุคคล | D13: Per trip when applicable
A14: 4. Trip-Specific Operational Cost | B14: ค่าทางด่วน | C14: ฝ่ายขนส่ง | D14: Actual per trip
B15: ค่าผ่านท่า / ค่าธรรมเนียมท่า | C15: ฝ่ายขนส่ง | D15: Actual per trip
B16: ค่าจอดรถ | C16: ฝ่ายขนส่ง | D16: Actual per trip
B17: ค่าใช้จ่ายเบ็ดเตล็ด / ค่าใช้จ่ายไม่มีใบเสร็จ | C17: ฝ่ายขนส่ง | D17: Actual or standard rate
A18: 5. Vehicle-Specific Cost | B18: ค่าน้ำมันเครื่องกำเนิดไฟฟ้าตู้เย็น | C18: ฝ่ายซ่อมบำรุง / ฝ่ายบัญชี | D18: Consumption × operating hours × fuel price
B19: ค่าใช้อุปกรณ์เฉพาะทางอื่น ๆ | C19: ฝ่ายซ่อมบำรุง / ฝ่ายบัญชี | D19: Per trip / hour / km
A20: 6. Overhead Allocation | B20: ค่าใช้จ่ายสำนักงานและธุรการ | D20: Allocate across trips using selected basis
B21: ค่าใช้จ่ายงานจัดรถ วางแผน และระบบ | D21: Allocate across trips
A22: 7. Capital / Economic Cost | B22: ต้นทุนค่าเสียโอกาสของเงินทุนในรถ | C22: Executive decision | D22: Allocate by trip/day/km
B23: ต้นทุนทางการเงิน / ดอกเบี้ย | C23: Executive decision | D23: If relevant
A24: 8. Risk Cost | B24: ต้นทุนคาดการณ์จากอุบัติเหตุ ความเสียหาย หรือการสูญหาย | C24: Educated assumption | D24: Expected loss per trip
B25: ต้นทุนความเสี่ยงเฉพาะเส้นทาง / ลูกค้า | C25: Educated assumption | D25: Add only where measurable

Sheet Assumption
A1: โมเดลคำนวณต้นทุนและราคาค่าขนส่งรถแต่ละประเภท
A2: วิธีใช้: แก้ไขเฉพาะช่องพื้นสีเหลือง (ตัวเลขสีน้ำเงิน) เท่านั้น | ช่องตัวอักษรสีดำ = สูตรคำนวณ ห้ามแก้
B4: ก. ข้อมูลเส้นทาง / Utilization | D4: ระยะทางเที่ยวเดียว | E4: 120
B5: รายการ | C5: หน่วยงานที่เกี่ยวข้อง | D5: 4W - Dry | E5: 4W - Reefer | F5: 6W - Dry | G5: 6W - Reefer | H5: 10W - Dry | I5: 10W - Reefer | J5: Container - Dry | K5: Container - Reefer | L5: Drayage - Dry | M5: Drayage - Reefer | N5: หน่วย | O5: ที่มา / หมายเหตุ
B6: ระยะทางเที่ยวเดียว | D6: =$E$4 -> 120 | E6: =$E$4 -> 120 | F6: =$E$4 -> 120 | G6: =$E$4 -> 120 | H6: =$E$4 -> 120 | I6: =$E$4 -> 120 | J6: =$E$4 -> 120 | K6: =$E$4 -> 120 | ... M6: =$E$4 -> 120 | N6: กม. | O6: โจทย์จากผู้ใช้
B7: ระยะทางรอบ Round trip | D7: 2 | E7: 2 | F7: 2 | G7: 2 | H7: 2 | I7: 2 | J7: 2 | K7: 2 | L7: 2 | M7: 2 | N7: เที่ยว | O7: ต้นทุนต้องคิดจากเที่ยวไปกลับ
B8: ระยะทางที่คิดค่าขนส่ง (Billable km) | D8: =D6*D7 -> 240 | E8: =E6*E7 -> 240 | F8: =F6*F7 -> 240 | G8: =G6*G7 -> 240 | H8: =H6*H7 -> 240 | I8: =I6*I7 -> 240 | J8: =J6*J7 -> 240 | K8: =K6*K7 -> 240 | ... M8: =M6*M7 -> 240 | N8: กม. | O8: สูตร: ระยะทางเที่ยวเดียว x จำนวนขา
B9: จำนวนเที่ยวงาน/คัน/เดือน | C9: ฝ่ายขนส่ง | D9: 25 | E9: 25 | F9: 25 | G9: 25 | H9: 25 | I9: 25 | J9: 25 | K9: 25 | L9: 25 | M9: 25 | N9: เที่ยว | O9: สมมติฐาน: ทำงาน 25 วัน/เดือน วันละ 1 เที่ยว (แก้ตามจริง)
B10: จำนวนเที่ยวงาน/คัน/ปี | D10: =D9*12 -> 300 | E10: =E9*12 -> 300 | F10: =F9*12 -> 300 | G10: =G9*12 -> 300 | H10: =H9*12 -> 300 | I10: =I9*12 -> 300 | J10: =J9*12 -> 300 | K10: =K9*12 -> 300 | ... M10: =M9*12 -> 300 | N10: เที่ยว | O10: สูตร: เที่ยว/เดือน x 12
B11: ระยะทางเกณฑ์ปรับเบี้ยเลี้ยง/ค่าใช้จ่าย (Threshold) | D11: 200 | E11: 200 | F11: 200 | G11: 200 | H11: 200 | I11: 200 | J11: 200 | K11: 200 | L11: 200 | M11: 200 | N11: กม. | O11: หากระยะทางที่คิดค่าขนส่ง (แถว 8) เกินค่านี้ คิดเบี้ยเลี้ยงและค่าใช้จ่ายไม่มีใบเสร็จเป็น 2 เท่า
B12: ข. ต้นทุนผันแปรตามระยะทาง (Variable Cost - บาท/กม.)
B13: รายการ | C13: หน่วยงานที่เกี่ยวข้อง | D13: 4W - Dry | E13: 4W - Reefer | F13: 6W - Dry | G13: 6W - Reefer | H13: 10W - Dry | I13: 10W - Reefer | J13: Container - Dry | K13: Container - Reefer | L13: Drayage - Dry | M13: Drayage - Reefer | N13: หน่วย | O13: ที่มา / หมายเหตุ
B14: ราคาน้ำมันดีเซล | D14: 48 | E14: 48 | F14: 48 | G14: 48 | H14: 48 | I14: 48 | J14: 48 | K14: 48 | L14: 48 | M14: 48 | N14: บาท/ลิตร | O14: โจทย์จากผู้ใช้
B15: อัตราสิ้นเปลืองน้ำมัน | C15: ฝ่ายขนส่ง | D15: 9.6 | E15: 9.6 | F15: 3.8 | G15: 3.8 | H15: 3.4 | I15: 3.4 | J15: 2.5 | K15: 2.5 | L15: 2.5 | M15: 2.5 | N15: กม./ลิตร | O15: จากตารางต้นทุนเดิม
B16: ต้นทุนน้ำมันเชื้อเพลิง | D16: =D14/D15 -> 5 | E16: =E14/E15 -> 5 | F16: =F14/F15 -> 12.631579 | G16: =G14/G15 -> 12.631579 | H16: =H14/H15 -> 14.117647 | I16: =I14/I15 -> 14.117647 | J16: =J14/J15 -> 19.2 | K16: =K14/K15 -> 19.2 | ... M16: =M14/M15 -> 19.2 | N16: บาท/กม. | O16: สูตร: ราคาน้ำมัน / อัตราสิ้นเปลือง
B17: ค่าน้ำมันหล่อลื่น+ไส้กรอง ต่อรอบเปลี่ยน | C17: ฝ่ายซ่อมบำรุง | D17: 1500 | E17: 1500 | F17: 3000 | G17: 3000 | H17: 6000 | I17: 6000 | J17: 10000 | K17: 10000 | L17: 10000 | M17: 10000 | N17: บาท/รอบ | O17: จากตารางเดิม (ตีความว่า 10,000 บาท ต่อรอบเปลี่ยนถ่าย)
B18: ระยะเปลี่ยนถ่ายน้ำมันเครื่อง | C18: ฝ่ายซ่อมบำรุง | D18: 10000 | E18: 10000 | F18: 10000 | G18: 10000 | H18: 10000 | I18: 10000 | J18: 10000 | K18: 10000 | L18: 10000 | M18: 10000 | N18: กม./รอบ | O18: สมมติฐานมาตรฐานรถหัวลาก - แก้ตามคู่มือรถจริง
B19: ต้นทุนน้ำมันหล่อลื่น | D19: =D17/D18 -> 0.15 | E19: =E17/E18 -> 0.15 | F19: =F17/F18 -> 0.3 | G19: =G17/G18 -> 0.3 | H19: =H17/H18 -> 0.6 | I19: =I17/I18 -> 0.6 | J19: =J17/J18 -> 1 | K19: =K17/K18 -> 1 | ... M19: =M17/M18 -> 1 | N19: บาท/กม. | O19: สูตร: ค่าน้ำมันหล่อลื่นต่อรอบ / ระยะเปลี่ยนถ่าย
B20: จำนวนยาง ต่อ คัน | D20: 4 | E20: 4 | F20: 6 | G20: 6 | H20: 10 | I20: 10 | J20: 22 | K20: 22 | L20: 22 | M20: 22 | N20: เส้น
B21: ราคายาง ต่อ เส้น | C21: ฝ่ายซ่อมบำรุง | D21: 3500 | E21: 3500 | F21: 5000 | G21: 5000 | H21: 6000 | I21: 6000 | J21: 10000 | K21: 10000 | L21: 10000 | M21: 10000 | N21: บาท
B22: ราคายางทั้งหมด | D22: =D20*D21 -> 14000 | E22: =E20*E21 -> 14000 | F22: =F20*F21 -> 30000 | G22: =G20*G21 -> 30000 | H22: =H20*H21 -> 60000 | I22: =I20*I21 -> 60000 | J22: =J20*J21 -> 220000 | K22: =K20*K21 -> 220000 | ... M22: =M20*M21 -> 220000 | N22: บาท/ชุด | O22: สมมติฐาน 22 เส้น x 10,000 บาท - แก้ตามราคาซื้อจริง
B23: อายุการใช้งานยาง | C23: ฝ่ายซ่อมบำรุง | D23: 50000 | E23: 50000 | F23: 80000 | G23: 80000 | H23: 100000 | I23: 100000 | J23: 100000 | K23: 100000 | L23: 100000 | M23: 100000 | N23: กม. | O23: สมมติฐาน - แก้ตามสถิติของบริษัท
B24: ต้นทุนค่ายางรถ | D24: =D22/D23 -> 0.28 | E24: =E22/E23 -> 0.28 | F24: =F22/F23 -> 0.375 | G24: =G22/G23 -> 0.375 | H24: =H22/H23 -> 0.6 | I24: =I22/I23 -> 0.6 | J24: =J22/J23 -> 2.2 | K24: =K22/K23 -> 2.2 | ... M24: =M22/M23 -> 2.2 | N24: บาท/กม. | O24: สูตร: ราคายาง / อายุยาง
B25: ค่าซ่อมบำรุง (ช่วงล่าง/เบรก/อะไหล่) | D25: 0.4 | E25: 0.4 | F25: 1.1 | G25: 1.1 | H25: 1.5 | I25: 1.5 | J25: 1.5 | K25: 1.5 | L25: 1.5 | M25: 1.5 | N25: บาท/กม. | O25: สมมติฐาน - ควรแทนที่ด้วยค่าซ่อมจริงย้อนหลัง 12 เดือน หาร กม.สะสม
B27: รวมต้นทุนผันแปรรถเย็น (Running Cost) | D27: =D16+D19+D24+D25 -> 5.83 | E27: =E16+E19+E24+E25 -> 5.83 | F27: =F16+F19+F24+F25 -> 14.406579 | G27: =G16+G19+G24+G25 -> 14.406579 | H27: =H16+H19+H24+H25 -> 16.817647 | I27: =I16+I19+I24+I25 -> 16.817647 | J27: =J16+J19+J24+J25 -> 23.9 | K27: =K16+K19+K24+K25 -> 23.9 | ... M27: =M16+M19+M24+M25 -> 23.9 | N27: บาท/กม.
B28: อัตราสิ้นเปลืองน้ำมันเจนเซ็ตตู้เย็น | D28: 0 | E28: 3.75 | F28: 0 | G28: 3.75 | H28: 0 | I28: 3.75 | J28: 0 | K28: 4 | L28: 0 | M28: 4 | N28: ลิตร/ชม. | O28: สมมติฐาน 3.5-4 ลิตร/ชม. (งาน Dry = 0) - แก้ตามสเปคเครื่องทำความเย็นจริง
B29: ความเร็วเฉลี่ยที่ใช้วิ่ง (ไม่เกินกฎหมายกำหนด) | D29: 90 | E29: 90 | F29: 90 | G29: 90 | H29: 90 | I29: 90 | J29: 65 | K29: 65 | L29: 65 | M29: 65 | N29: กม./ชม. | O29: กฎกระทรวงฯ พ.ศ. 2564 (ทางหลวง): รถบรรทุกเกิน 2,200 กก. ไม่เกิน 90 กม./ชม. | รถลากจูง (หัวลาก+หางพ่วง) ไม่เกิน 65 กม./ชม.
B30: ชั่วโมงเดินเครื่องทำความเย็น ต่อเที่ยว (ขาบรรทุกเที่ยวเดียว) | D30: =IF(D28>0,D6/D29,0) -> 0 | E30: =IF(E28>0,E6/E29,0) -> 1.3333333 | F30: =IF(F28>0,F6/F29,0) -> 0 | G30: =IF(G28>0,G6/G29,0) -> 1.3333333 | H30: =IF(H28>0,H6/H29,0) -> 0 | I30: =IF(I28>0,I6/I29,0) -> 1.3333333 | J30: =IF(J28>0,J6/J29,0) -> 0 | K30: =IF(K28>0,K6/K29,0) -> 1.8461538 | ... M30: =IF(M28>0,M6/M29,0) -> 1.8461538 | N30: ชม./เที่ยว | O30: สูตร: ระยะทางเที่ยวเดียว (แถว 6) / ความเร็วเฉลี่ย (แถว 29) | งาน Dry = 0
B31: ต้นทุนน้ำมันเจนเซ็ตตู้เย็น | D31: =D28*D30*D14 -> 0 | E31: =E28*E30*E14 -> 240 | F31: =F28*F30*F14 -> 0 | G31: =G28*G30*G14 -> 240 | H31: =H28*H30*H14 -> 0 | I31: =I28*I30*I14 -> 240 | J31: =J28*J30*J14 -> 0 | K31: =K28*K30*K14 -> 354.46154 | ... M31: =M28*M30*M14 -> 354.46154 | N31: บาท/เที่ยว | O31: สูตร: อัตราสิ้นเปลือง x ชั่วโมงเดินเครื่อง x ราคาน้ำมันดีเซล (แถว 14)
B33: ค. ต้นทุนคงที่ (Fixed Cost) - ปันส่วนเข้าเที่ยววิ่ง
B34: รายการ | C34: หน่วยงานที่เกี่ยวข้อง | D34: 4W - Dry | E34: 4W - Reefer | F34: 6W - Dry | G34: 6W - Reefer | H34: 10W - Dry | I34: 10W - Reefer | J34: Container - Dry | K34: Container - Reefer | L34: Drayage - Dry | M34: Drayage - Reefer | N34: หน่วย | O34: ที่มา / หมายเหตุ
B35: เงินเดือนพนักงานขับรถ | C35: ฝ่ายบุคคล | D35: 12000 | E35: 12000 | F35: 12000 | G35: 12000 | H35: 12000 | I35: 12000 | J35: 12000 | K35: 12000 | L35: =30*400 -> 12000 | M35: 12000 | N35: บาท/เดือน | O35: จากตารางต้นทุนเดิม
B36: ค่าเบี้ยเลี้ยงพนักงาน | C36: ฝ่ายบุคคล | D36: =IF(D$8>D$11,D45*2,D45) -> 600 | E36: =IF(E$8>E$11,E45*2,E45) -> 600 | F36: =IF(F$8>F$11,F45*2,F45) -> 800 | G36: =IF(G$8>G$11,G45*2,G45) -> 800 | H36: =IF(H$8>H$11,H45*2,H45) -> 1000 | I36: =IF(I$8>I$11,I45*2,I45) -> 1000 | J36: =IF(J$8>J$11,J45*2,J45) -> 1000 | K36: =IF(K$8>K$11,K45*2,K45) -> 1000 | ... M36: =IF(M$8>M$11,M45*2,M45) -> 1000 | N36: บาท/เที่ยว | O36: สูตร: ถ้าระยะทาง (แถว 8) > เกณฑ์ (แถว 11) ให้คิด 2 เท่าของอัตราฐาน (แถว 41)
B37: ค่าประกันสินค้าเสียหาย + เบี้ยประกันภัยรถ | C37: ฝ่ายขนส่ง | D37: 25000 | E37: 25000 | F37: 40000 | G37: 40000 | H37: 60000 | I37: 60000 | J37: 110000 | K37: 120000 | L37: 110000 | M37: 120000 | N37: บาท/ปี | O37: จากตารางต้นทุนเดิม
B38: ภาษีประจำปี หัว-หาง+GPS | C38: ฝ่ายขนส่ง | D38: 5000 | E38: 5000 | F38: 6500 | G38: 6500 | H38: 8000 | I38: 8000 | J38: 10000 | K38: 10000 | L38: 10000 | M38: 10000 | N38: บาท/ปี | O38: จากตารางต้นทุนเดิม
B39: ค่าใช้จ่ายไม่มีใบเสร็จ (ค่าทางด่วน/ค่าผ่านท่า/เบ็ดเตล็ด) | C39: ฝ่ายขนส่ง | D39: =IF(D$8>D$11,D46*2,D46) -> 400 | E39: =IF(E$8>E$11,E46*2,E46) -> 400 | F39: =IF(F$8>F$11,F46*2,F46) -> 500 | G39: =IF(G$8>G$11,G46*2,G46) -> 500 | H39: =IF(H$8>H$11,H46*2,H46) -> 600 | I39: =IF(I$8>I$11,I46*2,I46) -> 600 | J39: =IF(J$8>J$11,J46*2,J46) -> 600 | K39: =IF(K$8>K$11,K46*2,K46) -> 600 | ... M39: =IF(M$8>M$11,M46*2,M46) -> 600 | N39: บาท/เที่ยว | O39: สูตร: ถ้าระยะทาง (แถว 8) > เกณฑ์ (แถว 11) ให้คิด 2 เท่าของอัตราฐาน (แถว 42)
B40: ค่าใช้จ่ายสำนักงาน (Overhead ปันส่วน) | C40: ฝ่ายขนส่ง | D40: 6000 | E40: 6000 | F40: 7000 | G40: 7000 | H40: 8000 | I40: 8000 | J40: 10000 | K40: 10000 | L40: 10000 | M40: 10000 | N40: บาท/คัน/เดือน | O40: สมมติฐาน - ควรใช้ค่าใช้จ่ายสำนักงานรวมทั้งปี / จำนวนรถ / 12
B41: ราคาลงทุนรถ | C41: ฝ่ายบัญชี | D41: 900000 | E41: 1300000 | F41: 1900000 | G41: 2600000 | H41: 2900000 | I41: 3700000 | J41: 4100000 | K41: 4600000 | L41: 4100000 | M41: 4600000 | N41: บาท | O41: สมมติฐาน (หัว 3.5 ลบ. + หาง 0.6 ลบ.) - แก้ตามราคาซื้อจริง
B42: มูลค่าซาก (% ของราคารถ) | C42: ฝ่ายบัญชี | D42: 0.05 | E42: 0.05 | F42: 0.05 | G42: 0.05 | H42: 0.05 | I42: 0.05 | J42: 0.05 | K42: 0.05 | L42: 0.05 | M42: 0.05 | N42: % | O42: สมมติฐาน
B43: อายุการใช้งาน (คิดค่าเสื่อม) | C43: ฝ่ายบัญชี | D43: 15 | E43: 15 | F43: 15 | G43: 15 | H43: 15 | I43: 15 | J43: 15 | K43: 15 | L43: 15 | M43: 15 | N43: ปี | O43: สมมติฐาน - หากรถปลอดหนี้/ตัดค่าเสื่อมหมดแล้ว ให้ใส่ค่าเสื่อม = 0
...

Sheet Summary
A1: โครงสร้างต้นทุนต่อเที่ยว (Cost Build-up per Trip)
A2: อ้างอิงตัวเลขทั้งหมดจากชีต 'Assumption' (ตัวอักษรสีเขียว = ลิงก์ข้ามชีต) | P2: หมายเหตุเดิม (ย้ายจากตารางเก่า)
D3: Domestic Template | L3: Drayage Template | P3: ใช้รถเราเอง
B4: รายการ | C4: หน่วย | D4: =Assumption!D5 -> 4W - Dry | E4: =Assumption!E5 -> 4W - Reefer | F4: =Assumption!F5 -> 6W - Dry | G4: =Assumption!G5 -> 6W - Reefer | H4: =Assumption!H5 -> 10W - Dry | I4: =Assumption!I5 -> 10W - Reefer | J4: =Assumption!J5 -> Container - Dry | K4: =Assumption!K5 -> Container - Reefer | ... M4: =Assumption!M5 -> Drayage - Reefer | P4: น้ำมันเจนเซ็ต 4 บาท/ลิตร | อัตราสิ้นเปลือง 3.5-4 L/ชั่วโมง
B5: ระยะทางที่คิดค่าขนส่ง | C5: กม./เที่ยว | D5: =Assumption!D8 -> 240 | E5: =Assumption!E8 -> 240 | F5: =Assumption!F8 -> 240 | G5: =Assumption!G8 -> 240 | H5: =Assumption!H8 -> 240 | I5: =Assumption!I8 -> 240 | J5: =Assumption!J8 -> 240 | K5: =Assumption!K8 -> 240 | ... M5: =Assumption!M8 -> 240 | P5: ราคาห้ามต่ำกว่านี้ - ถ้าราคาต่ำกว่าจะต้องมีการเปรียบเทียบราคา
B6: จำนวนเที่ยวงาน/คัน/เดือน | C6: เที่ยว | D6: =Assumption!D9 -> 25 | E6: =Assumption!E9 -> 25 | F6: =Assumption!F9 -> 25 | G6: =Assumption!G9 -> 25 | H6: =Assumption!H9 -> 25 | I6: =Assumption!I9 -> 25 | J6: =Assumption!J9 -> 25 | K6: =Assumption!K9 -> 25 | ... M6: =Assumption!M9 -> 25 | P6: ค่าเช่า/อ้างอิง 170,000
B7: จำนวนเที่ยวงาน/คัน/ปี | C7: เที่ยว | D7: =Assumption!D10 -> 300 | E7: =Assumption!E10 -> 300 | F7: =Assumption!F10 -> 300 | G7: =Assumption!G10 -> 300 | H7: =Assumption!H10 -> 300 | I7: =Assumption!I10 -> 300 | J7: =Assumption!J10 -> 300 | K7: =Assumption!K10 -> 300 | ... M7: =Assumption!M10 -> 300
B9: ต้นทุนต่อเที่ยว (บาท/เที่ยว)
B10: ค่าน้ำมันเชื้อเพลิง | C10: บาท/กม. x ระยะทาง | D10: =Assumption!D16*D$5 -> 1200 | E10: =Assumption!E16*E$5 -> 1200 | F10: =Assumption!F16*F$5 -> 3031.5789 | G10: =Assumption!G16*G$5 -> 3031.5789 | H10: =Assumption!H16*H$5 -> 3388.2353 | I10: =Assumption!I16*I$5 -> 3388.2353 | J10: =Assumption!J16*J$5 -> 4608 | K10: =Assumption!K16*K$5 -> 4608 | ... M10: =Assumption!M16*M$5 -> 4608
B11: ค่าน้ำมันหล่อลื่น + ไส้กรอง | C11: บาท/กม. x ระยะทาง | D11: =Assumption!D19*D$5 -> 36 | E11: =Assumption!E19*E$5 -> 36 | F11: =Assumption!F19*F$5 -> 72 | G11: =Assumption!G19*G$5 -> 72 | H11: =Assumption!H19*H$5 -> 144 | I11: =Assumption!I19*I$5 -> 144 | J11: =Assumption!J19*J$5 -> 240 | K11: =Assumption!K19*K$5 -> 240 | ... M11: =Assumption!M19*M$5 -> 240
B12: ค่ายางรถ | C12: บาท/กม. x ระยะทาง | D12: =Assumption!D24*D$5 -> 67.2 | E12: =Assumption!E24*E$5 -> 67.2 | F12: =Assumption!F24*F$5 -> 90 | G12: =Assumption!G24*G$5 -> 90 | H12: =Assumption!H24*H$5 -> 144 | I12: =Assumption!I24*I$5 -> 144 | J12: =Assumption!J24*J$5 -> 528 | K12: =Assumption!K24*K$5 -> 528 | ... M12: =Assumption!M24*M$5 -> 528
B13: ค่าซ่อมบำรุง | C13: บาท/กม. x ระยะทาง | D13: =Assumption!D25*D$5 -> 96 | E13: =Assumption!E25*E$5 -> 96 | F13: =Assumption!F25*F$5 -> 264 | G13: =Assumption!G25*G$5 -> 264 | H13: =Assumption!H25*H$5 -> 360 | I13: =Assumption!I25*I$5 -> 360 | J13: =Assumption!J25*J$5 -> 360 | K13: =Assumption!K25*K$5 -> 360 | ... M13: =Assumption!M25*M$5 -> 360
B14: ค่าเบี้ยเลี้ยงพนักงานขับรถ | C14: ตรง 1 เที่ยว | D14: =Assumption!D36 -> 600 | E14: =Assumption!E36 -> 600 | F14: =Assumption!F36 -> 800 | G14: =Assumption!G36 -> 800 | H14: =Assumption!H36 -> 1000 | I14: =Assumption!I36 -> 1000 | J14: =Assumption!J36 -> 1000 | K14: =Assumption!K36 -> 1000 | ... M14: =Assumption!M36 -> 1000
B15: ค่าใช้จ่ายไม่มีใบเสร็จ (ทางด่วน/ผ่านท่า) | C15: ตรง 1 เที่ยว | D15: =Assumption!D39 -> 400 | E15: =Assumption!E39 -> 400 | F15: =Assumption!F39 -> 500 | G15: =Assumption!G39 -> 500 | H15: =Assumption!H39 -> 600 | I15: =Assumption!I39 -> 600 | J15: =Assumption!J39 -> 600 | K15: =Assumption!K39 -> 600 | ... M15: =Assumption!M39 -> 600
B16: เงินเดือนพนักงานขับรถ | C16: / เที่ยวต่อเดือน | D16: =Assumption!D35/D$6 -> 480 | E16: =Assumption!E35/E$6 -> 480 | F16: =Assumption!F35/F$6 -> 480 | G16: =Assumption!G35/G$6 -> 480 | H16: =Assumption!H35/H$6 -> 480 | I16: =Assumption!I35/I$6 -> 480 | J16: =Assumption!J35/J$6 -> 480 | K16: =Assumption!K35/K$6 -> 480 | ... M16: =Assumption!M35/M$6 -> 480
B17: ค่าใช้จ่ายสำนักงาน (Overhead) | C17: / เที่ยวต่อเดือน | D17: =Assumption!D40/D$6 -> 240 | E17: =Assumption!E40/E$6 -> 240 | F17: =Assumption!F40/F$6 -> 280 | G17: =Assumption!G40/G$6 -> 280 | H17: =Assumption!H40/H$6 -> 320 | I17: =Assumption!I40/I$6 -> 320 | J17: =Assumption!J40/J$6 -> 400 | K17: =Assumption!K40/K$6 -> 400 | ... M17: =Assumption!M40/M$6 -> 400
B18: ค่าประกันสินค้า + ประกันภัยรถ | C18: / เที่ยวต่อปี | D18: =Assumption!D37/D$7 -> 83.333333 | E18: =Assumption!E37/E$7 -> 83.333333 | F18: =Assumption!F37/F$7 -> 133.33333 | G18: =Assumption!G37/G$7 -> 133.33333 | H18: =Assumption!H37/H$7 -> 200 | I18: =Assumption!I37/I$7 -> 200 | J18: =Assumption!J37/J$7 -> 366.66667 | K18: =Assumption!K37/K$7 -> 400 | ... M18: =Assumption!M37/M$7 -> 400
B19: ภาษีประจำปี หัว-หาง + GPS | C19: / เที่ยวต่อปี | D19: =Assumption!D38/D$7 -> 16.666667 | E19: =Assumption!E38/E$7 -> 16.666667 | F19: =Assumption!F38/F$7 -> 21.666667 | G19: =Assumption!G38/G$7 -> 21.666667 | H19: =Assumption!H38/H$7 -> 26.666667 | I19: =Assumption!I38/I$7 -> 26.666667 | J19: =Assumption!J38/J$7 -> 33.333333 | K19: =Assumption!K38/K$7 -> 33.333333 | ... M19: =Assumption!M38/M$7 -> 33.333333
B20: ค่าเสื่อมราคารถ | C20: / เที่ยวต่อปี | D20: =Assumption!D44/D$7 -> 190 | E20: =Assumption!E44/E$7 -> 274.44444 | F20: =Assumption!F44/F$7 -> 401.11111 | G20: =Assumption!G44/G$7 -> 548.88889 | H20: =Assumption!H44/H$7 -> 612.22222 | I20: =Assumption!I44/I$7 -> 781.11111 | J20: =Assumption!J44/J$7 -> 865.55556 | K20: =Assumption!K44/K$7 -> 971.11111 | ... M20: =Assumption!M44/M$7 -> 971.11111
B21: ค่าน้ำมันเจนเซ็ตตู้เย็น (Reefer) | C21: ตรง 1 เที่ยว | D21: =Assumption!D31 -> 0 | E21: =Assumption!E31 -> 240 | F21: =Assumption!F31 -> 0 | G21: =Assumption!G31 -> 240 | H21: =Assumption!H31 -> 0 | I21: =Assumption!I31 -> 240 | J21: =Assumption!J31 -> 0 | K21: =Assumption!K31 -> 354.46154 | ... M21: =Assumption!M31 -> 354.46154
B22: รวมต้นทุนต่อเที่ยว (Total Cost) | C22: บาท/เที่ยว | D22: =SUM(D10:D21) -> 3409.2 | E22: =SUM(E10:E21) -> 3733.6444 | F22: =SUM(F10:F21) -> 6073.6901 | G22: =SUM(G10:G21) -> 6461.4678 | H22: =SUM(H10:H21) -> 7275.1242 | I22: =SUM(I10:I21) -> 7684.0131 | J22: =SUM(J10:J21) -> 9481.5556 | K22: =SUM(K10:K21) -> 9974.906 | ... M22: =SUM(M10:M21) -> 9974.906
B23: ต้นทุนต่อกิโลเมตร (Cost per km) | C23: บาท/กม. | D23: =IFERROR(D22/D$5,0) -> 14.205 | E23: =IFERROR(E22/E$5,0) -> 15.556852 | F23: =IFERROR(F22/F$5,0) -> 25.307042 | G23: =IFERROR(G22/G$5,0) -> 26.922783 | H23: =IFERROR(H22/H$5,0) -> 30.313017 | I23: =IFERROR(I22/I$5,0) -> 32.016721 | J23: =IFERROR(J22/J$5,0) -> 39.506481 | K23: =IFERROR(K22/K$5,0) -> 41.562108 | ... M23: =IFERROR(M22/M$5,0) -> 41.562108
B24: อัตรากำไรเป้าหมาย (Margin) | C24: % | D24: 0.3 | E24: 0.3 | F24: 0.3 | G24: 0.3 | H24: 0.3 | I24: 0.3 | J24: 0.3 | K24: 0.3 | L24: 0.3 | M24: 0.3
B25: กำไรเป้าหมาย | C25: บาท/เที่ยว | D25: =D22/(1-D24)-D22 -> 1461.0857 | E25: =E22/(1-E24)-E22 -> 1600.1333 | F25: =F22/(1-F24)-F22 -> 2603.01 | G25: =G22/(1-G24)-G22 -> 2769.2005 | H25: =H22/(1-H24)-H22 -> 3117.9104 | I25: =I22/(1-I24)-I22 -> 3293.1485 | J25: =J22/(1-J24)-J22 -> 4063.5238 | K25: =K22/(1-K24)-K22 -> 4274.9597 | ... M25: =M22/(1-M24)-M22 -> 4274.9597
B26: ราคาเสนอขาย (Standard Selling Price) | C26: บาท/เที่ยว | D26: =D22+D25 -> 4870.2857 | E26: =E22+E25 -> 5333.7778 | F26: =F22+F25 -> 8676.7001 | G26: =G22+G25 -> 9230.6683 | H26: =H22+H25 -> 10393.035 | I26: =I22+I25 -> 10977.162 | J26: =J22+J25 -> 13545.079 | K26: =K22+K25 -> 14249.866 | ... M26: =M22+M25 -> 14249.866
B27: ราคาเสนอขายต่อกิโลเมตร | C27: บาท/กม. | D27: =IFERROR(D26/D$5,0) -> 20.292857 | E27: =IFERROR(E26/E$5,0) -> 22.224074 | F27: =IFERROR(F26/F$5,0) -> 36.152917 | G27: =IFERROR(G26/G$5,0) -> 38.461118 | H27: =IFERROR(H26/H$5,0) -> 43.304311 | I27: =IFERROR(I26/I$5,0) -> 45.738173 | J27: =IFERROR(J26/J$5,0) -> 56.437831 | K27: =IFERROR(K26/K$5,0) -> 59.37444 | ... M27: =IFERROR(M26/M$5,0) -> 59.37444
B29: หมายเหตุ: ราคานี้ยังไม่รวม VAT 7% และยังไม่หักภาษี ณ ที่จ่าย 1%
B30: ค่าบริการเพิ่มเติม: ค่ารอเกินเวลา / ค่าเพิ่มดรอป คิดตามชีต Assumption ข้อ ง. / งานค้างคืนหรือตู้ Reefer-Danger ให้บวกเพิ่มแยกต่างหาก

Sheet Sheet2
A1: Vin Number ของแต่ละประเภทรถ
A2: Driver name, number
A3: Maintenance checklist
C5: 4W | D5: 6W | E5: 10W | F5: Container | G5: KPI
A6: VIN no. | B6: Preventive Maintenance | G6: Completeness of Preventive Maintenance
B7: Periodic Maintenance | G7: Cost per truck
B8: Failure Maintenance | G8: Time-to-failure
